[2022-06-23 01:17:32,898] {taskinstance.py:1159} INFO - Dependencies all met for <TaskInstance: test.my_etl scheduled__2022-06-21T00:00:00+00:00 [queued]>
[2022-06-23 01:17:32,909] {taskinstance.py:1159} INFO - Dependencies all met for <TaskInstance: test.my_etl scheduled__2022-06-21T00:00:00+00:00 [queued]>
[2022-06-23 01:17:32,909] {taskinstance.py:1356} INFO - 
--------------------------------------------------------------------------------
[2022-06-23 01:17:32,909] {taskinstance.py:1357} INFO - Starting attempt 1 of 2
[2022-06-23 01:17:32,909] {taskinstance.py:1358} INFO - 
--------------------------------------------------------------------------------
[2022-06-23 01:17:32,951] {taskinstance.py:1377} INFO - Executing <Task(PythonOperator): my_etl> on 2022-06-21 00:00:00+00:00
[2022-06-23 01:17:32,960] {standard_task_runner.py:52} INFO - Started process 121 to run task
[2022-06-23 01:17:32,964] {standard_task_runner.py:79} INFO - Running: ['***', 'tasks', 'run', 'test', 'my_etl', 'scheduled__2022-06-21T00:00:00+00:00', '--job-id', '249', '--raw', '--subdir', 'DAGS_FOLDER/test-dag.py', '--cfg-path', '/tmp/tmps2k361b2', '--error-file', '/tmp/tmpni39sbhs']
[2022-06-23 01:17:32,965] {standard_task_runner.py:80} INFO - Job 249: Subtask my_etl
[2022-06-23 01:17:33,048] {task_command.py:370} INFO - Running <TaskInstance: test.my_etl scheduled__2022-06-21T00:00:00+00:00 [running]> on host ca189b65812b
[2022-06-23 01:17:33,376] {taskinstance.py:1571} INFO - Exporting the following env vars:
AIRFLOW_CTX_DAG_OWNER=***
AIRFLOW_CTX_DAG_ID=test
AIRFLOW_CTX_TASK_ID=my_etl
AIRFLOW_CTX_EXECUTION_DATE=2022-06-21T00:00:00+00:00
AIRFLOW_CTX_TRY_NUMBER=1
AIRFLOW_CTX_DAG_RUN_ID=scheduled__2022-06-21T00:00:00+00:00
[2022-06-23 01:17:41,888] {taskinstance.py:1889} ERROR - Task failed with exception
Traceback (most recent call last):
  File "/home/airflow/.local/lib/python3.7/site-packages/airflow/operators/python.py", line 171, in execute
    return_value = self.execute_callable()
  File "/home/airflow/.local/lib/python3.7/site-packages/airflow/operators/python.py", line 189, in execute_callable
    return self.python_callable(*self.op_args, **self.op_kwargs)
  File "/opt/airflow/dags/job_etl.py", line 75, in run_job_etl
    job_desription.append(soup2.find('div', 'jobsearch-jobDescriptionText').get_text())
AttributeError: 'NoneType' object has no attribute 'get_text'
[2022-06-23 01:17:41,971] {taskinstance.py:1400} INFO - Marking task as UP_FOR_RETRY. dag_id=test, task_id=my_etl, execution_date=20220621T000000, start_date=20220623T011732, end_date=20220623T011741
[2022-06-23 01:17:42,027] {standard_task_runner.py:97} ERROR - Failed to execute job 249 for task my_etl ('NoneType' object has no attribute 'get_text'; 121)
[2022-06-23 01:17:42,051] {local_task_job.py:156} INFO - Task exited with return code 1
[2022-06-23 01:17:42,135] {local_task_job.py:273} INFO - 0 downstream tasks scheduled from follow-on schedule check
