[2022-07-08 21:38:42,040] {taskinstance.py:1159} INFO - Dependencies all met for <TaskInstance: test.load_data scheduled__2022-07-06T00:00:00+00:00 [queued]>
[2022-07-08 21:38:42,059] {taskinstance.py:1159} INFO - Dependencies all met for <TaskInstance: test.load_data scheduled__2022-07-06T00:00:00+00:00 [queued]>
[2022-07-08 21:38:42,059] {taskinstance.py:1356} INFO - 
--------------------------------------------------------------------------------
[2022-07-08 21:38:42,059] {taskinstance.py:1357} INFO - Starting attempt 1 of 2
[2022-07-08 21:38:42,059] {taskinstance.py:1358} INFO - 
--------------------------------------------------------------------------------
[2022-07-08 21:38:42,097] {taskinstance.py:1377} INFO - Executing <Task(PythonOperator): load_data> on 2022-07-06 00:00:00+00:00
[2022-07-08 21:38:42,109] {standard_task_runner.py:52} INFO - Started process 885 to run task
[2022-07-08 21:38:42,117] {standard_task_runner.py:79} INFO - Running: ['***', 'tasks', 'run', 'test', 'load_data', 'scheduled__2022-07-06T00:00:00+00:00', '--job-id', '379', '--raw', '--subdir', 'DAGS_FOLDER/test-dag.py', '--cfg-path', '/tmp/tmpzj8z_hb3', '--error-file', '/tmp/tmp0sdf99s_']
[2022-07-08 21:38:42,118] {standard_task_runner.py:80} INFO - Job 379: Subtask load_data
[2022-07-08 21:38:42,212] {task_command.py:370} INFO - Running <TaskInstance: test.load_data scheduled__2022-07-06T00:00:00+00:00 [running]> on host 3c0196e07a8e
[2022-07-08 21:38:42,360] {taskinstance.py:1571} INFO - Exporting the following env vars:
AIRFLOW_CTX_DAG_OWNER=***
AIRFLOW_CTX_DAG_ID=test
AIRFLOW_CTX_TASK_ID=load_data
AIRFLOW_CTX_EXECUTION_DATE=2022-07-06T00:00:00+00:00
AIRFLOW_CTX_TRY_NUMBER=1
AIRFLOW_CTX_DAG_RUN_ID=scheduled__2022-07-06T00:00:00+00:00
[2022-07-08 21:38:42,362] {taskinstance.py:1889} ERROR - Task failed with exception
Traceback (most recent call last):
  File "/home/airflow/.local/lib/python3.7/site-packages/airflow/operators/python.py", line 171, in execute
    return_value = self.execute_callable()
  File "/home/airflow/.local/lib/python3.7/site-packages/airflow/operators/python.py", line 189, in execute_callable
    return self.python_callable(*self.op_args, **self.op_kwargs)
  File "/opt/airflow/dags/SLTrack.py", line 148, in load_satellite_data
    data = pd.read_json('/home/L/Programming/dataEng/spaceApp/spacTrackAPI/TLEData.json')
  File "/home/airflow/.local/lib/python3.7/site-packages/pandas/util/_decorators.py", line 207, in wrapper
    return func(*args, **kwargs)
  File "/home/airflow/.local/lib/python3.7/site-packages/pandas/util/_decorators.py", line 311, in wrapper
    return func(*args, **kwargs)
  File "/home/airflow/.local/lib/python3.7/site-packages/pandas/io/json/_json.py", line 614, in read_json
    return json_reader.read()
  File "/home/airflow/.local/lib/python3.7/site-packages/pandas/io/json/_json.py", line 748, in read
    obj = self._get_object_parser(self.data)
  File "/home/airflow/.local/lib/python3.7/site-packages/pandas/io/json/_json.py", line 770, in _get_object_parser
    obj = FrameParser(json, **kwargs).parse()
  File "/home/airflow/.local/lib/python3.7/site-packages/pandas/io/json/_json.py", line 885, in parse
    self._parse_no_numpy()
  File "/home/airflow/.local/lib/python3.7/site-packages/pandas/io/json/_json.py", line 1140, in _parse_no_numpy
    loads(json, precise_float=self.precise_float), dtype=None
ValueError: Expected object or value
[2022-07-08 21:38:42,375] {taskinstance.py:1400} INFO - Marking task as UP_FOR_RETRY. dag_id=test, task_id=load_data, execution_date=20220706T000000, start_date=20220708T213842, end_date=20220708T213842
[2022-07-08 21:38:42,455] {standard_task_runner.py:97} ERROR - Failed to execute job 379 for task load_data (Expected object or value; 885)
[2022-07-08 21:38:42,493] {local_task_job.py:156} INFO - Task exited with return code 1
[2022-07-08 21:38:42,611] {local_task_job.py:273} INFO - 0 downstream tasks scheduled from follow-on schedule check
