[2022-07-08 22:05:21,242] {taskinstance.py:1159} INFO - Dependencies all met for <TaskInstance: test.api_request manual__2022-07-08T22:00:18.973947+00:00 [queued]>
[2022-07-08 22:05:21,251] {taskinstance.py:1159} INFO - Dependencies all met for <TaskInstance: test.api_request manual__2022-07-08T22:00:18.973947+00:00 [queued]>
[2022-07-08 22:05:21,251] {taskinstance.py:1356} INFO - 
--------------------------------------------------------------------------------
[2022-07-08 22:05:21,251] {taskinstance.py:1357} INFO - Starting attempt 2 of 2
[2022-07-08 22:05:21,251] {taskinstance.py:1358} INFO - 
--------------------------------------------------------------------------------
[2022-07-08 22:05:21,267] {taskinstance.py:1377} INFO - Executing <Task(PythonOperator): api_request> on 2022-07-08 22:00:18.973947+00:00
[2022-07-08 22:05:21,272] {standard_task_runner.py:52} INFO - Started process 2191 to run task
[2022-07-08 22:05:21,276] {standard_task_runner.py:79} INFO - Running: ['***', 'tasks', 'run', 'test', 'api_request', 'manual__2022-07-08T22:00:18.973947+00:00', '--job-id', '398', '--raw', '--subdir', 'DAGS_FOLDER/test-dag.py', '--cfg-path', '/tmp/tmpbclz_724', '--error-file', '/tmp/tmph2vxghg0']
[2022-07-08 22:05:21,277] {standard_task_runner.py:80} INFO - Job 398: Subtask api_request
[2022-07-08 22:05:21,351] {task_command.py:370} INFO - Running <TaskInstance: test.api_request manual__2022-07-08T22:00:18.973947+00:00 [running]> on host 3c0196e07a8e
[2022-07-08 22:05:21,485] {taskinstance.py:1571} INFO - Exporting the following env vars:
AIRFLOW_CTX_DAG_OWNER=***
AIRFLOW_CTX_DAG_ID=test
AIRFLOW_CTX_TASK_ID=api_request
AIRFLOW_CTX_EXECUTION_DATE=2022-07-08T22:00:18.973947+00:00
AIRFLOW_CTX_TRY_NUMBER=2
AIRFLOW_CTX_DAG_RUN_ID=manual__2022-07-08T22:00:18.973947+00:00
[2022-07-08 22:05:21,487] {taskinstance.py:1889} ERROR - Task failed with exception
Traceback (most recent call last):
  File "/home/airflow/.local/lib/python3.7/site-packages/airflow/operators/python.py", line 171, in execute
    return_value = self.execute_callable()
  File "/home/airflow/.local/lib/python3.7/site-packages/airflow/operators/python.py", line 189, in execute_callable
    return self.python_callable(*self.op_args, **self.op_kwargs)
  File "/opt/airflow/dags/SLTrack.py", line 117, in api_call
    configUsr = config.get("configuration","username")
  File "/usr/local/lib/python3.7/configparser.py", line 780, in get
    d = self._unify_values(section, vars)
  File "/usr/local/lib/python3.7/configparser.py", line 1146, in _unify_values
    raise NoSectionError(section) from None
configparser.NoSectionError: No section: 'configuration'
[2022-07-08 22:05:21,496] {taskinstance.py:1400} INFO - Marking task as FAILED. dag_id=test, task_id=api_request, execution_date=20220708T220018, start_date=20220708T220521, end_date=20220708T220521
[2022-07-08 22:05:21,526] {standard_task_runner.py:97} ERROR - Failed to execute job 398 for task api_request (No section: 'configuration'; 2191)
[2022-07-08 22:05:21,567] {local_task_job.py:156} INFO - Task exited with return code 1
[2022-07-08 22:05:21,626] {local_task_job.py:273} INFO - 0 downstream tasks scheduled from follow-on schedule check
