[2022-06-24 06:23:52,236] {taskinstance.py:1159} INFO - Dependencies all met for <TaskInstance: test.my_etl manual__2022-06-24T06:18:44.803514+00:00 [queued]>
[2022-06-24 06:23:52,247] {taskinstance.py:1159} INFO - Dependencies all met for <TaskInstance: test.my_etl manual__2022-06-24T06:18:44.803514+00:00 [queued]>
[2022-06-24 06:23:52,247] {taskinstance.py:1356} INFO - 
--------------------------------------------------------------------------------
[2022-06-24 06:23:52,247] {taskinstance.py:1357} INFO - Starting attempt 2 of 2
[2022-06-24 06:23:52,247] {taskinstance.py:1358} INFO - 
--------------------------------------------------------------------------------
[2022-06-24 06:23:52,271] {taskinstance.py:1377} INFO - Executing <Task(PythonOperator): my_etl> on 2022-06-24 06:18:44.803514+00:00
[2022-06-24 06:23:52,277] {standard_task_runner.py:52} INFO - Started process 323 to run task
[2022-06-24 06:23:52,281] {standard_task_runner.py:79} INFO - Running: ['***', 'tasks', 'run', 'test', 'my_etl', 'manual__2022-06-24T06:18:44.803514+00:00', '--job-id', '310', '--raw', '--subdir', 'DAGS_FOLDER/test-dag.py', '--cfg-path', '/tmp/tmpmo_wt00v', '--error-file', '/tmp/tmpxmvi0pvc']
[2022-06-24 06:23:52,282] {standard_task_runner.py:80} INFO - Job 310: Subtask my_etl
[2022-06-24 06:23:52,349] {task_command.py:370} INFO - Running <TaskInstance: test.my_etl manual__2022-06-24T06:18:44.803514+00:00 [running]> on host 3c0196e07a8e
[2022-06-24 06:23:52,524] {taskinstance.py:1571} INFO - Exporting the following env vars:
AIRFLOW_CTX_DAG_OWNER=***
AIRFLOW_CTX_DAG_ID=test
AIRFLOW_CTX_TASK_ID=my_etl
AIRFLOW_CTX_EXECUTION_DATE=2022-06-24T06:18:44.803514+00:00
AIRFLOW_CTX_TRY_NUMBER=2
AIRFLOW_CTX_DAG_RUN_ID=manual__2022-06-24T06:18:44.803514+00:00
[2022-06-24 06:24:02,110] {taskinstance.py:1889} ERROR - Task failed with exception
Traceback (most recent call last):
  File "/home/airflow/.local/lib/python3.7/site-packages/airflow/operators/python.py", line 171, in execute
    return_value = self.execute_callable()
  File "/home/airflow/.local/lib/python3.7/site-packages/airflow/operators/python.py", line 189, in execute_callable
    return self.python_callable(*self.op_args, **self.op_kwargs)
  File "/opt/airflow/dags/test-dag.py", line 25, in func
    df1.to_csv('planetDataDownload/data.csv')
  File "/home/airflow/.local/lib/python3.7/site-packages/pandas/core/generic.py", line 3482, in to_csv
    storage_options=storage_options,
  File "/home/airflow/.local/lib/python3.7/site-packages/pandas/io/formats/format.py", line 1105, in to_csv
    csv_formatter.save()
  File "/home/airflow/.local/lib/python3.7/site-packages/pandas/io/formats/csvs.py", line 243, in save
    storage_options=self.storage_options,
  File "/home/airflow/.local/lib/python3.7/site-packages/pandas/io/common.py", line 707, in get_handle
    newline="",
FileNotFoundError: [Errno 2] No such file or directory: 'planetDataDownload/data.csv'
[2022-06-24 06:24:02,122] {taskinstance.py:1400} INFO - Marking task as FAILED. dag_id=test, task_id=my_etl, execution_date=20220624T061844, start_date=20220624T062352, end_date=20220624T062402
[2022-06-24 06:24:02,188] {standard_task_runner.py:97} ERROR - Failed to execute job 310 for task my_etl ([Errno 2] No such file or directory: 'planetDataDownload/data.csv'; 323)
[2022-06-24 06:24:02,228] {local_task_job.py:156} INFO - Task exited with return code 1
[2022-06-24 06:24:02,288] {local_task_job.py:273} INFO - 0 downstream tasks scheduled from follow-on schedule check
