[2022-07-08 21:35:41,272] {taskinstance.py:1159} INFO - Dependencies all met for <TaskInstance: test.api_request scheduled__2022-07-03T00:00:00+00:00 [queued]>
[2022-07-08 21:35:41,282] {taskinstance.py:1159} INFO - Dependencies all met for <TaskInstance: test.api_request scheduled__2022-07-03T00:00:00+00:00 [queued]>
[2022-07-08 21:35:41,282] {taskinstance.py:1356} INFO - 
--------------------------------------------------------------------------------
[2022-07-08 21:35:41,282] {taskinstance.py:1357} INFO - Starting attempt 1 of 2
[2022-07-08 21:35:41,283] {taskinstance.py:1358} INFO - 
--------------------------------------------------------------------------------
[2022-07-08 21:35:41,329] {taskinstance.py:1377} INFO - Executing <Task(PythonOperator): api_request> on 2022-07-03 00:00:00+00:00
[2022-07-08 21:35:41,336] {standard_task_runner.py:52} INFO - Started process 705 to run task
[2022-07-08 21:35:41,340] {standard_task_runner.py:79} INFO - Running: ['***', 'tasks', 'run', 'test', 'api_request', 'scheduled__2022-07-03T00:00:00+00:00', '--job-id', '366', '--raw', '--subdir', 'DAGS_FOLDER/test-dag.py', '--cfg-path', '/tmp/tmpdnmbjq6l', '--error-file', '/tmp/tmp2x1ksrlx']
[2022-07-08 21:35:41,341] {standard_task_runner.py:80} INFO - Job 366: Subtask api_request
[2022-07-08 21:35:41,448] {task_command.py:370} INFO - Running <TaskInstance: test.api_request scheduled__2022-07-03T00:00:00+00:00 [running]> on host 3c0196e07a8e
[2022-07-08 21:35:41,585] {taskinstance.py:1571} INFO - Exporting the following env vars:
AIRFLOW_CTX_DAG_OWNER=***
AIRFLOW_CTX_DAG_ID=test
AIRFLOW_CTX_TASK_ID=api_request
AIRFLOW_CTX_EXECUTION_DATE=2022-07-03T00:00:00+00:00
AIRFLOW_CTX_TRY_NUMBER=1
AIRFLOW_CTX_DAG_RUN_ID=scheduled__2022-07-03T00:00:00+00:00
[2022-07-08 21:35:41,586] {taskinstance.py:1889} ERROR - Task failed with exception
Traceback (most recent call last):
  File "/home/airflow/.local/lib/python3.7/site-packages/airflow/operators/python.py", line 171, in execute
    return_value = self.execute_callable()
  File "/home/airflow/.local/lib/python3.7/site-packages/airflow/operators/python.py", line 189, in execute_callable
    return self.python_callable(*self.op_args, **self.op_kwargs)
  File "/opt/airflow/dags/SLTrack.py", line 117, in api_call
    configUsr = config.get("configuration","username")
  File "/usr/local/lib/python3.7/configparser.py", line 780, in get
    d = self._unify_values(section, vars)
  File "/usr/local/lib/python3.7/configparser.py", line 1146, in _unify_values
    raise NoSectionError(section) from None
configparser.NoSectionError: No section: 'configuration'
[2022-07-08 21:35:41,594] {taskinstance.py:1400} INFO - Marking task as UP_FOR_RETRY. dag_id=test, task_id=api_request, execution_date=20220703T000000, start_date=20220708T213541, end_date=20220708T213541
[2022-07-08 21:35:41,627] {standard_task_runner.py:97} ERROR - Failed to execute job 366 for task api_request (No section: 'configuration'; 705)
[2022-07-08 21:35:41,670] {local_task_job.py:156} INFO - Task exited with return code 1
[2022-07-08 21:35:41,727] {local_task_job.py:273} INFO - 0 downstream tasks scheduled from follow-on schedule check
