[2022-07-08 22:00:00,628] {taskinstance.py:1159} INFO - Dependencies all met for <TaskInstance: test.load_data scheduled__2022-07-03T00:00:00+00:00 [queued]>
[2022-07-08 22:00:00,643] {taskinstance.py:1159} INFO - Dependencies all met for <TaskInstance: test.load_data scheduled__2022-07-03T00:00:00+00:00 [queued]>
[2022-07-08 22:00:00,643] {taskinstance.py:1356} INFO - 
--------------------------------------------------------------------------------
[2022-07-08 22:00:00,643] {taskinstance.py:1357} INFO - Starting attempt 2 of 2
[2022-07-08 22:00:00,643] {taskinstance.py:1358} INFO - 
--------------------------------------------------------------------------------
[2022-07-08 22:00:00,681] {taskinstance.py:1377} INFO - Executing <Task(PythonOperator): load_data> on 2022-07-03 00:00:00+00:00
[2022-07-08 22:00:00,687] {standard_task_runner.py:52} INFO - Started process 1924 to run task
[2022-07-08 22:00:00,689] {standard_task_runner.py:79} INFO - Running: ['***', 'tasks', 'run', 'test', 'load_data', 'scheduled__2022-07-03T00:00:00+00:00', '--job-id', '386', '--raw', '--subdir', 'DAGS_FOLDER/test-dag.py', '--cfg-path', '/tmp/tmp76tag058', '--error-file', '/tmp/tmpb9excqp8']
[2022-07-08 22:00:00,689] {standard_task_runner.py:80} INFO - Job 386: Subtask load_data
[2022-07-08 22:00:00,780] {task_command.py:370} INFO - Running <TaskInstance: test.load_data scheduled__2022-07-03T00:00:00+00:00 [running]> on host 3c0196e07a8e
[2022-07-08 22:00:01,022] {taskinstance.py:1571} INFO - Exporting the following env vars:
AIRFLOW_CTX_DAG_OWNER=***
AIRFLOW_CTX_DAG_ID=test
AIRFLOW_CTX_TASK_ID=load_data
AIRFLOW_CTX_EXECUTION_DATE=2022-07-03T00:00:00+00:00
AIRFLOW_CTX_TRY_NUMBER=2
AIRFLOW_CTX_DAG_RUN_ID=scheduled__2022-07-03T00:00:00+00:00
[2022-07-08 22:00:01,023] {taskinstance.py:1889} ERROR - Task failed with exception
Traceback (most recent call last):
  File "/home/airflow/.local/lib/python3.7/site-packages/airflow/operators/python.py", line 171, in execute
    return_value = self.execute_callable()
  File "/home/airflow/.local/lib/python3.7/site-packages/airflow/operators/python.py", line 189, in execute_callable
    return self.python_callable(*self.op_args, **self.op_kwargs)
  File "/opt/airflow/dags/SLTrack.py", line 155, in load_satellite_data
    data = pd.read_json('/home/L/Programming/dataEng/spaceApp/spacTrackAPI/TLEData.json')
  File "/home/airflow/.local/lib/python3.7/site-packages/pandas/util/_decorators.py", line 207, in wrapper
    return func(*args, **kwargs)
  File "/home/airflow/.local/lib/python3.7/site-packages/pandas/util/_decorators.py", line 311, in wrapper
    return func(*args, **kwargs)
  File "/home/airflow/.local/lib/python3.7/site-packages/pandas/io/json/_json.py", line 614, in read_json
    return json_reader.read()
  File "/home/airflow/.local/lib/python3.7/site-packages/pandas/io/json/_json.py", line 748, in read
    obj = self._get_object_parser(self.data)
  File "/home/airflow/.local/lib/python3.7/site-packages/pandas/io/json/_json.py", line 770, in _get_object_parser
    obj = FrameParser(json, **kwargs).parse()
  File "/home/airflow/.local/lib/python3.7/site-packages/pandas/io/json/_json.py", line 885, in parse
    self._parse_no_numpy()
  File "/home/airflow/.local/lib/python3.7/site-packages/pandas/io/json/_json.py", line 1140, in _parse_no_numpy
    loads(json, precise_float=self.precise_float), dtype=None
ValueError: Expected object or value
[2022-07-08 22:00:01,038] {taskinstance.py:1400} INFO - Marking task as FAILED. dag_id=test, task_id=load_data, execution_date=20220703T000000, start_date=20220708T220000, end_date=20220708T220001
[2022-07-08 22:00:01,095] {standard_task_runner.py:97} ERROR - Failed to execute job 386 for task load_data (Expected object or value; 1924)
[2022-07-08 22:00:01,105] {local_task_job.py:156} INFO - Task exited with return code 1
[2022-07-08 22:00:01,181] {local_task_job.py:273} INFO - 0 downstream tasks scheduled from follow-on schedule check
