[2022-06-24 06:19:41,846] {taskinstance.py:1159} INFO - Dependencies all met for <TaskInstance: test.my_etl scheduled__2022-06-23T00:00:00+00:00 [queued]>
[2022-06-24 06:19:41,856] {taskinstance.py:1159} INFO - Dependencies all met for <TaskInstance: test.my_etl scheduled__2022-06-23T00:00:00+00:00 [queued]>
[2022-06-24 06:19:41,856] {taskinstance.py:1356} INFO - 
--------------------------------------------------------------------------------
[2022-06-24 06:19:41,856] {taskinstance.py:1357} INFO - Starting attempt 2 of 2
[2022-06-24 06:19:41,856] {taskinstance.py:1358} INFO - 
--------------------------------------------------------------------------------
[2022-06-24 06:19:41,879] {taskinstance.py:1377} INFO - Executing <Task(PythonOperator): my_etl> on 2022-06-23 00:00:00+00:00
[2022-06-24 06:19:41,887] {standard_task_runner.py:52} INFO - Started process 127 to run task
[2022-06-24 06:19:41,891] {standard_task_runner.py:79} INFO - Running: ['***', 'tasks', 'run', 'test', 'my_etl', 'scheduled__2022-06-23T00:00:00+00:00', '--job-id', '309', '--raw', '--subdir', 'DAGS_FOLDER/test-dag.py', '--cfg-path', '/tmp/tmp6epdji9v', '--error-file', '/tmp/tmp2xgsy4vy']
[2022-06-24 06:19:41,892] {standard_task_runner.py:80} INFO - Job 309: Subtask my_etl
[2022-06-24 06:19:41,967] {task_command.py:370} INFO - Running <TaskInstance: test.my_etl scheduled__2022-06-23T00:00:00+00:00 [running]> on host 3c0196e07a8e
[2022-06-24 06:19:42,082] {taskinstance.py:1571} INFO - Exporting the following env vars:
AIRFLOW_CTX_DAG_OWNER=***
AIRFLOW_CTX_DAG_ID=test
AIRFLOW_CTX_TASK_ID=my_etl
AIRFLOW_CTX_EXECUTION_DATE=2022-06-23T00:00:00+00:00
AIRFLOW_CTX_TRY_NUMBER=2
AIRFLOW_CTX_DAG_RUN_ID=scheduled__2022-06-23T00:00:00+00:00
[2022-06-24 06:19:45,995] {taskinstance.py:1889} ERROR - Task failed with exception
Traceback (most recent call last):
  File "/home/airflow/.local/lib/python3.7/site-packages/airflow/operators/python.py", line 171, in execute
    return_value = self.execute_callable()
  File "/home/airflow/.local/lib/python3.7/site-packages/airflow/operators/python.py", line 189, in execute_callable
    return self.python_callable(*self.op_args, **self.op_kwargs)
  File "/opt/airflow/dags/test-dag.py", line 25, in func
    df1.to_csv('planetDataDownload/data.csv')
  File "/home/airflow/.local/lib/python3.7/site-packages/pandas/core/generic.py", line 3482, in to_csv
    storage_options=storage_options,
  File "/home/airflow/.local/lib/python3.7/site-packages/pandas/io/formats/format.py", line 1105, in to_csv
    csv_formatter.save()
  File "/home/airflow/.local/lib/python3.7/site-packages/pandas/io/formats/csvs.py", line 243, in save
    storage_options=self.storage_options,
  File "/home/airflow/.local/lib/python3.7/site-packages/pandas/io/common.py", line 707, in get_handle
    newline="",
FileNotFoundError: [Errno 2] No such file or directory: 'planetDataDownload/data.csv'
[2022-06-24 06:19:46,010] {taskinstance.py:1400} INFO - Marking task as FAILED. dag_id=test, task_id=my_etl, execution_date=20220623T000000, start_date=20220624T061941, end_date=20220624T061946
[2022-06-24 06:19:46,038] {standard_task_runner.py:97} ERROR - Failed to execute job 309 for task my_etl ([Errno 2] No such file or directory: 'planetDataDownload/data.csv'; 127)
[2022-06-24 06:19:46,073] {local_task_job.py:156} INFO - Task exited with return code 1
[2022-06-24 06:19:46,137] {local_task_job.py:273} INFO - 0 downstream tasks scheduled from follow-on schedule check
