[2022-07-08 22:08:33,230] {taskinstance.py:1159} INFO - Dependencies all met for <TaskInstance: test.api_request manual__2022-07-08T22:08:32.070021+00:00 [queued]>
[2022-07-08 22:08:33,241] {taskinstance.py:1159} INFO - Dependencies all met for <TaskInstance: test.api_request manual__2022-07-08T22:08:32.070021+00:00 [queued]>
[2022-07-08 22:08:33,241] {taskinstance.py:1356} INFO - 
--------------------------------------------------------------------------------
[2022-07-08 22:08:33,241] {taskinstance.py:1357} INFO - Starting attempt 1 of 2
[2022-07-08 22:08:33,242] {taskinstance.py:1358} INFO - 
--------------------------------------------------------------------------------
[2022-07-08 22:08:33,295] {taskinstance.py:1377} INFO - Executing <Task(PythonOperator): api_request> on 2022-07-08 22:08:32.070021+00:00
[2022-07-08 22:08:33,300] {standard_task_runner.py:52} INFO - Started process 2356 to run task
[2022-07-08 22:08:33,304] {standard_task_runner.py:79} INFO - Running: ['***', 'tasks', 'run', 'test', 'api_request', 'manual__2022-07-08T22:08:32.070021+00:00', '--job-id', '402', '--raw', '--subdir', 'DAGS_FOLDER/test-dag.py', '--cfg-path', '/tmp/tmpadrma_wg', '--error-file', '/tmp/tmp__k1h0o6']
[2022-07-08 22:08:33,305] {standard_task_runner.py:80} INFO - Job 402: Subtask api_request
[2022-07-08 22:08:33,379] {task_command.py:370} INFO - Running <TaskInstance: test.api_request manual__2022-07-08T22:08:32.070021+00:00 [running]> on host 3c0196e07a8e
[2022-07-08 22:08:33,556] {taskinstance.py:1571} INFO - Exporting the following env vars:
AIRFLOW_CTX_DAG_OWNER=***
AIRFLOW_CTX_DAG_ID=test
AIRFLOW_CTX_TASK_ID=api_request
AIRFLOW_CTX_EXECUTION_DATE=2022-07-08T22:08:32.070021+00:00
AIRFLOW_CTX_TRY_NUMBER=1
AIRFLOW_CTX_DAG_RUN_ID=manual__2022-07-08T22:08:32.070021+00:00
[2022-07-08 22:08:33,557] {taskinstance.py:1889} ERROR - Task failed with exception
Traceback (most recent call last):
  File "/home/airflow/.local/lib/python3.7/site-packages/airflow/operators/python.py", line 171, in execute
    return_value = self.execute_callable()
  File "/home/airflow/.local/lib/python3.7/site-packages/airflow/operators/python.py", line 189, in execute_callable
    return self.python_callable(*self.op_args, **self.op_kwargs)
  File "/opt/airflow/dags/SLTrack.py", line 117, in api_call
    configUsr = config.get("configuration","username")
  File "/usr/local/lib/python3.7/configparser.py", line 780, in get
    d = self._unify_values(section, vars)
  File "/usr/local/lib/python3.7/configparser.py", line 1146, in _unify_values
    raise NoSectionError(section) from None
configparser.NoSectionError: No section: 'configuration'
[2022-07-08 22:08:33,568] {taskinstance.py:1400} INFO - Marking task as UP_FOR_RETRY. dag_id=test, task_id=api_request, execution_date=20220708T220832, start_date=20220708T220833, end_date=20220708T220833
[2022-07-08 22:08:33,644] {standard_task_runner.py:97} ERROR - Failed to execute job 402 for task api_request (No section: 'configuration'; 2356)
[2022-07-08 22:08:33,675] {local_task_job.py:156} INFO - Task exited with return code 1
[2022-07-08 22:08:33,767] {local_task_job.py:273} INFO - 0 downstream tasks scheduled from follow-on schedule check
